[2024-10-01T07:28:41.229+0000] {taskinstance.py:1103} INFO - Dependencies all met for dep_context=non-requeueable deps ti=<TaskInstance: email_notification.load_data_task manual__2024-10-01T07:28:38.888443+00:00 [queued]>
[2024-10-01T07:28:41.238+0000] {taskinstance.py:1103} INFO - Dependencies all met for dep_context=requeueable deps ti=<TaskInstance: email_notification.load_data_task manual__2024-10-01T07:28:38.888443+00:00 [queued]>
[2024-10-01T07:28:41.239+0000] {taskinstance.py:1308} INFO - Starting attempt 2 of 3
[2024-10-01T07:28:41.253+0000] {taskinstance.py:1327} INFO - Executing <Task(PythonOperator): load_data_task> on 2024-10-01 07:28:38.888443+00:00
[2024-10-01T07:28:41.260+0000] {standard_task_runner.py:57} INFO - Started process 105 to run task
[2024-10-01T07:28:41.262+0000] {standard_task_runner.py:84} INFO - Running: ['***', 'tasks', 'run', 'email_notification', 'load_data_task', 'manual__2024-10-01T07:28:38.888443+00:00', '--job-id', '94', '--raw', '--subdir', 'DAGS_FOLDER/email_notification.py', '--cfg-path', '/tmp/tmpq4_hfuah']
[2024-10-01T07:28:41.263+0000] {standard_task_runner.py:85} INFO - Job 94: Subtask load_data_task
[2024-10-01T07:28:41.307+0000] {task_command.py:410} INFO - Running <TaskInstance: email_notification.load_data_task manual__2024-10-01T07:28:38.888443+00:00 [running]> on host 4658b6cf8d09
[2024-10-01T07:28:41.387+0000] {taskinstance.py:1547} INFO - Exporting env vars: AIRFLOW_CTX_DAG_EMAIL='phurinatkantapayao@gmail.com' AIRFLOW_CTX_DAG_OWNER='***' AIRFLOW_CTX_DAG_ID='email_notification' AIRFLOW_CTX_TASK_ID='load_data_task' AIRFLOW_CTX_EXECUTION_DATE='2024-10-01T07:28:38.888443+00:00' AIRFLOW_CTX_TRY_NUMBER='2' AIRFLOW_CTX_DAG_RUN_ID='manual__2024-10-01T07:28:38.888443+00:00'
[2024-10-01T07:28:41.388+0000] {taskinstance.py:1824} ERROR - Task failed with exception
Traceback (most recent call last):
  File "/home/airflow/.local/lib/python3.7/site-packages/airflow/operators/python.py", line 181, in execute
    return_value = self.execute_callable()
  File "/home/airflow/.local/lib/python3.7/site-packages/airflow/operators/python.py", line 198, in execute_callable
    return self.python_callable(*self.op_args, **self.op_kwargs)
  File "/opt/airflow/dags/email_notification.py", line 6, in load_data
    raise Exception("Python function error")
Exception: Python function error
[2024-10-01T07:28:41.398+0000] {taskinstance.py:1350} INFO - Marking task as UP_FOR_RETRY. dag_id=email_notification, task_id=load_data_task, execution_date=20241001T072838, start_date=20241001T072841, end_date=20241001T072841
[2024-10-01T07:28:41.409+0000] {standard_task_runner.py:109} ERROR - Failed to execute job 94 for task load_data_task (Python function error; 105)
[2024-10-01T07:28:41.434+0000] {local_task_job_runner.py:225} INFO - Task exited with return code 1
[2024-10-01T07:28:41.455+0000] {taskinstance.py:2653} INFO - 0 downstream tasks scheduled from follow-on schedule check
