[2024-10-01T08:04:48.134+0000] {taskinstance.py:1103} INFO - Dependencies all met for dep_context=non-requeueable deps ti=<TaskInstance: email_notification.load_data_task manual__2024-10-01T08:04:46.715350+00:00 [queued]>
[2024-10-01T08:04:48.147+0000] {taskinstance.py:1103} INFO - Dependencies all met for dep_context=requeueable deps ti=<TaskInstance: email_notification.load_data_task manual__2024-10-01T08:04:46.715350+00:00 [queued]>
[2024-10-01T08:04:48.147+0000] {taskinstance.py:1308} INFO - Starting attempt 1 of 3
[2024-10-01T08:04:48.165+0000] {taskinstance.py:1327} INFO - Executing <Task(PythonOperator): load_data_task> on 2024-10-01 08:04:46.715350+00:00
[2024-10-01T08:04:48.171+0000] {standard_task_runner.py:57} INFO - Started process 80 to run task
[2024-10-01T08:04:48.174+0000] {standard_task_runner.py:84} INFO - Running: ['***', 'tasks', 'run', 'email_notification', 'load_data_task', 'manual__2024-10-01T08:04:46.715350+00:00', '--job-id', '117', '--raw', '--subdir', 'DAGS_FOLDER/email_notification.py', '--cfg-path', '/tmp/tmpai0fh1qw']
[2024-10-01T08:04:48.175+0000] {standard_task_runner.py:85} INFO - Job 117: Subtask load_data_task
[2024-10-01T08:04:48.226+0000] {task_command.py:410} INFO - Running <TaskInstance: email_notification.load_data_task manual__2024-10-01T08:04:46.715350+00:00 [running]> on host f707d5feea40
[2024-10-01T08:04:48.317+0000] {taskinstance.py:1547} INFO - Exporting env vars: AIRFLOW_CTX_DAG_EMAIL='phurinatkantapayao@gmail.com' AIRFLOW_CTX_DAG_OWNER='***' AIRFLOW_CTX_DAG_ID='email_notification' AIRFLOW_CTX_TASK_ID='load_data_task' AIRFLOW_CTX_EXECUTION_DATE='2024-10-01T08:04:46.715350+00:00' AIRFLOW_CTX_TRY_NUMBER='1' AIRFLOW_CTX_DAG_RUN_ID='manual__2024-10-01T08:04:46.715350+00:00'
[2024-10-01T08:04:48.319+0000] {taskinstance.py:1824} ERROR - Task failed with exception
Traceback (most recent call last):
  File "/home/airflow/.local/lib/python3.7/site-packages/airflow/operators/python.py", line 181, in execute
    return_value = self.execute_callable()
  File "/home/airflow/.local/lib/python3.7/site-packages/airflow/operators/python.py", line 198, in execute_callable
    return self.python_callable(*self.op_args, **self.op_kwargs)
  File "/opt/airflow/dags/email_notification.py", line 6, in load_data
    raise Exception("Python function error")
Exception: Python function error
[2024-10-01T08:04:48.333+0000] {taskinstance.py:1350} INFO - Marking task as UP_FOR_RETRY. dag_id=email_notification, task_id=load_data_task, execution_date=20241001T080446, start_date=20241001T080448, end_date=20241001T080448
[2024-10-01T08:04:48.349+0000] {standard_task_runner.py:109} ERROR - Failed to execute job 117 for task load_data_task (Python function error; 80)
[2024-10-01T08:04:48.387+0000] {local_task_job_runner.py:225} INFO - Task exited with return code 1
[2024-10-01T08:04:48.407+0000] {taskinstance.py:2653} INFO - 0 downstream tasks scheduled from follow-on schedule check
