[2024-10-01T07:36:19.448+0000] {taskinstance.py:1103} INFO - Dependencies all met for dep_context=non-requeueable deps ti=<TaskInstance: email_notification.load_data_task manual__2024-10-01T07:36:16.661487+00:00 [queued]>
[2024-10-01T07:36:19.458+0000] {taskinstance.py:1103} INFO - Dependencies all met for dep_context=requeueable deps ti=<TaskInstance: email_notification.load_data_task manual__2024-10-01T07:36:16.661487+00:00 [queued]>
[2024-10-01T07:36:19.459+0000] {taskinstance.py:1308} INFO - Starting attempt 2 of 3
[2024-10-01T07:36:19.474+0000] {taskinstance.py:1327} INFO - Executing <Task(PythonOperator): load_data_task> on 2024-10-01 07:36:16.661487+00:00
[2024-10-01T07:36:19.481+0000] {standard_task_runner.py:57} INFO - Started process 249 to run task
[2024-10-01T07:36:19.484+0000] {standard_task_runner.py:84} INFO - Running: ['***', 'tasks', 'run', 'email_notification', 'load_data_task', 'manual__2024-10-01T07:36:16.661487+00:00', '--job-id', '103', '--raw', '--subdir', 'DAGS_FOLDER/email_notification.py', '--cfg-path', '/tmp/tmp9heh1w93']
[2024-10-01T07:36:19.485+0000] {standard_task_runner.py:85} INFO - Job 103: Subtask load_data_task
[2024-10-01T07:36:19.536+0000] {task_command.py:410} INFO - Running <TaskInstance: email_notification.load_data_task manual__2024-10-01T07:36:16.661487+00:00 [running]> on host 4658b6cf8d09
[2024-10-01T07:36:19.622+0000] {taskinstance.py:1547} INFO - Exporting env vars: AIRFLOW_CTX_DAG_EMAIL='aruethai.c@gmail.com' AIRFLOW_CTX_DAG_OWNER='***' AIRFLOW_CTX_DAG_ID='email_notification' AIRFLOW_CTX_TASK_ID='load_data_task' AIRFLOW_CTX_EXECUTION_DATE='2024-10-01T07:36:16.661487+00:00' AIRFLOW_CTX_TRY_NUMBER='2' AIRFLOW_CTX_DAG_RUN_ID='manual__2024-10-01T07:36:16.661487+00:00'
[2024-10-01T07:36:19.624+0000] {taskinstance.py:1824} ERROR - Task failed with exception
Traceback (most recent call last):
  File "/home/airflow/.local/lib/python3.7/site-packages/airflow/operators/python.py", line 181, in execute
    return_value = self.execute_callable()
  File "/home/airflow/.local/lib/python3.7/site-packages/airflow/operators/python.py", line 198, in execute_callable
    return self.python_callable(*self.op_args, **self.op_kwargs)
  File "/opt/airflow/dags/email_notification.py", line 6, in load_data
    raise Exception("Python function error")
Exception: Python function error
[2024-10-01T07:36:19.636+0000] {taskinstance.py:1350} INFO - Marking task as UP_FOR_RETRY. dag_id=email_notification, task_id=load_data_task, execution_date=20241001T073616, start_date=20241001T073619, end_date=20241001T073619
[2024-10-01T07:36:19.650+0000] {standard_task_runner.py:109} ERROR - Failed to execute job 103 for task load_data_task (Python function error; 249)
[2024-10-01T07:36:19.696+0000] {local_task_job_runner.py:225} INFO - Task exited with return code 1
[2024-10-01T07:36:19.718+0000] {taskinstance.py:2653} INFO - 0 downstream tasks scheduled from follow-on schedule check
